- [语法错误](#%E8%AF%AD%E6%B3%95%E9%94%99%E8%AF%AF)
- [异常](#%E5%BC%82%E5%B8%B8)
- [异常处理](#%E5%BC%82%E5%B8%B8%E5%A4%84%E7%90%86)
- [抛出异常](#%E6%8A%9B%E5%87%BA%E5%BC%82%E5%B8%B8)
- [用户自定义异常](#%E7%94%A8%E6%88%B7%E8%87%AA%E5%AE%9A%E4%B9%89%E5%BC%82%E5%B8%B8)
- [定义清理行为](#%E5%AE%9A%E4%B9%89%E6%B8%85%E7%90%86%E8%A1%8C%E4%B8%BA)
- [预定义清理行为](#%E9%A2%84%E5%AE%9A%E4%B9%89%E6%B8%85%E7%90%86%E8%A1%8C%E4%B8%BA)
---
## 语法错误
- 语法错误，也被称为解析错误，是一种基本的错误，出错后语法分析器会显示出错误的文件名和行号。
---
## 异常
- 在运行期间检测到的错误称为异常。即使一条语句在语法上是正确的，当执行的时候也可能引发错误。
```py
>>> 10 * (1/0)
Traceback (most recent call last):
  File "<stdin>", line 1, in ?
ZeroDivisionError: int division or modulo by zero
>>> 4 + spam*3
Traceback (most recent call last):
  File "<stdin>", line 1, in ?
NameError: name 'spam' is not defined
>>> '2' + 2
Traceback (most recent call last):
  File "<stdin>", line 1, in ?
TypeError: Can't convert 'int' object to str implicitly
```
> 异常也有不同的类型，示例中常见的异常分别为：零除错误(ZeroDivisionError)，命名错误(NameError)和类型错误(TypeError)。
---
## 异常处理
- 下面的例子：会一直要求用户输入，直到输入一个合法的整数为止，但允许用户中断这个程序(用户产生的中断会引发一个KeyboardInterrupt异常，使用ctrl+c)。
```py
>>> while True:
...     try:
...         x = int(input("Please enter a number: "))
...         break
...     except ValueError:
...         print("That was no valid number.  Try again...")
```
- try语句按如下方式工作：
    - 首先，执行`try`子句(在`try`和`except`关键字之间的部分)。
    - 如果没有异常发生，`except`子句在`try`语句执行完毕后就被忽略了。
    - 如果在`try`子句执行过程中发生了异常，那么该子句其余的部分就会被忽略。
    - 如果异常匹配于`except`关键字后面指定的异常类型，就执行对应的`except`子句。然后继续执行`try`语句之后的代码。
    - 如果发生了一个异常，在`except`子句中没有与之匹配的分支，它就会传递到上一级`try`语句中。
    - 如果最终仍找不到对应的处理语句，它就成为一个未处理异常，终止程序运行，显示提示信息。
- 一个`try`语句可能包含多个`except`子句，分别指定处理不同的异常。至多只会有一个分支被执行。
- 异常处理程序只会处理对应的`try`子句中发生的异常，在同一个`try`语句中，其他子句中发生的异常则不作处理。
- 一个`except`子句可以在括号中列出多个异常的名字，例如:
```py
... except (RuntimeError, TypeError, NameError):
...     pass
```
- 最后一个`except`子句可以省略异常名称，以作为通配符使用。但是要**慎用**，因为它会隐藏一个实际的程序错误。另外可以使用此方法打印一条错误信息，然后重新抛出异常(可进行异常处理)。
```py
try:
    pass
except error1 as e:
    pass
except error2 :
    pass
except :
    pass
    raise another err
```
- 在异常名之后，也可以为`except`子句指定一个变量。给异常传递一个参数(如果要传递多个参数，可以传递一个元组)，把它绑定到message属性。一旦异常发生，它会在抛出前绑定所有指定的属性。
```py
>>> try:
...    raise Exception('spam', 'eggs')
... except Exception as inst:
...    print(type(inst))    # the exception instance
...    print(inst.args)     # arguments stored in .args
...    print(inst)          # __str__ allows args to be printed directly,
...                         # but may be overridden in exception subclasses
...    x, y = inst.args     # unpack args
...    print('x =', x)
...    print('y =', y)
...
<class 'Exception'>
('spam', 'eggs')
('spam', 'eggs')
x = spam
y = eggs
```
- 对于那些未处理的异常，如果一个它们带有参数，那么就会被作为异常信息的最后部分（“详情”）打印出来。
- 异常处理器不仅仅处理那些在`try`子句中立刻发生的异常，也会处理那些`try`子句中调用的函数内部发生的异常。
```py
>>> def this_fails():
...     x = 1/0
...
>>> try:
...     this_fails()
... except ZeroDivisionError as err:
...     print('Handling run-time error:', err)
...
Handling run-time error: int division or modulo by zero
```
---
## 抛出异常
- `raise`语句允许强制抛出一个指定的异常。
- 要抛出的异常由`raise`的唯一参数标识。它必需是一个异常实例或异常类(继承自`Exception`的类)。
```py
>>> raise NameError('HiThere')
Traceback (most recent call last):
  File "<stdin>", line 1, in ?
NameError: HiThere
```
- 如果需要判断异常是否抛出，但是不需要处理，`raise`语句可以重新抛出该异常。
```py
>>> try:
...     raise NameError('HiThere')
... except NameError:
...     print('An exception flew by!')
...     raise
...
An exception flew by!
Traceback (most recent call last):
  File "<stdin>", line 2, in ?
NameError: HiThere
```
---
## 用户自定义异常
- 在程序中可以通过创建新的异常类型来命名自己的异常。
- 异常类通常应该直接或间接的从`Exception`类派生。
---
## 定义清理行为
- `try`语句还有另一个可选的子句，目的在于定义在任何情况下都一定要执行的功能。
```py
>>> try:
...     raise KeyboardInterrupt
... finally:
...     print('Goodbye, world!')
...
Goodbye, world!
KeyboardInterrupt
Traceback (most recent call last):
  File "<stdin>", line 2, in ?
```
- 不管有没有发生异常，`finally`子句在程序离开`try`后都一定会被执行。
- 当`try`语句中发生了未被`except`捕获的异常(或者它发生在except或else子句中)，在`finally`子句执行完后它会被重新抛出。`try`语句经由`break`,`continue`或`return`语句退出也一样会执行`finally`子句。
```py
>>> def divide(x, y):
...     try:
...         result = x / y
...     except ZeroDivisionError:
...         print("division by zero!")
...     else:
...         print("result is", result)
...     finally:
...         print("executing finally clause")
...
>>> divide(2, 1)
result is 2
executing finally clause
>>> divide(2, 0)
division by zero!
executing finally clause
>>> divide("2", "1")
executing finally clause
Traceback (most recent call last):
  File "<stdin>", line 1, in ?
  File "<stdin>", line 3, in divide
TypeError: unsupported operand type(s) for /: 'str' and 'str'
```
---
## 预定义清理行为
- 某些对象定义了标准的清理行为，无论对象操作是否成功，不需要该对象的时候就会自动清理。
> `with`语句可以使文件对象使用后得到及时准确的清理。
